Workbook
Name cfg_ConsNom: '[1]01 Configuration'!$B$72:$B$74
Name cfg_NivNom: '[1]01 Configuration'!$B$61:$B$66
Name cfg_TipoNom: '[1]01 Configuration'!$F$72:$F$74
Name lst_Dim: '[1]01 Configuration'!$AB$5:$AB$15
Name lst_Foco: '[1]01 Configuration'!$N$5:$N$7

Sheet INICIO - DASHBOARD
B2: #VALUE! | C2: EVALUACIÓN DE MADUREZ EN LA GESTIÓN DE FATIGA & SOMNOLENCIA - V01
B3: Guía de uso y acceso a las secciones de la herramienta / Dashboard resultados
B5: DATOS DE LA EVALUACIÓN
B6: Empresa
B7: Fecha de evaluación
B8: Realizado por
B9: Entrevistado
B11: OBJETIVO: | C11: Evaluar el nivel de madurez de la gestión de fatiga y somnolencia de la organización, identificando fortalezas, brechas y oportunidades de mejora en los procesos, controles y capacidades organizacionales, con el fin de priorizar acciones que reduzcan los riesgos para las personas, la seguridad operacional y la continuidad de las operaciones.
B13: METODOLOGÍA: | C13: La metodología utilizada es una evaluación cualitativa estructurada, basada en 12 dimensiones aplicando 128 preguntas de medición de cumplimiento (5 por componente) que entregan un nivel de porcentaje según una rúbrica de 5 niveles de madurez.
B15: RESULTADOS: | C15: Entrega una visión integral del estado de madurez de la gestión de fatiga y somnolencia, mostrando la posición de la organización respecto de las mejores prácticas y permitiendo priorizar iniciativas para fortalecer los controles, la cultura preventiva y la seguridad operacional.
B17: INSTRUCTIVO DE USO | M17: ESCALA CLASIFICACIÓN GENERAL NIVEL DE MADUREZ
B18: 1. Registre los antecedentes de la evaluación en los campos superiores.
B19: 2. Defina las dimensiones a aplicar | M19: Nivel 1 (0% - 39%) | N19: Inicial/Reactivo
B20: 3. Abra la hoja Preguntas y responda las 20 preguntas (5 por componente) seleccionando uno de los 5 criterios en la columna "Nivel de cumplimiento". Al inicio la celda indica "EVA" (EVALUAR). Al responder, se asigna un valor de 0%, 25%, 50%, 75% o 100% según el nivel de cumplimiento o gestión particular respecto a lo evaluado. | M20: Nivel 2 (40% - 59%) | N20: Dependiente
B21: 4. El DASHBOARD calcula automáticamente el cumplimiento de los cuatro componentes y el nivel global de BCM. | M21: Nivel 3 (60% - 79%) | N21: Independiente
B22: 5. Revise la hoja Escala: se resaltará el nivel alcanzado en cada componente con el color correspondiente. | M22: Nivel 4 (80% - 99%) | N22: Interdependiente
B23: 6. Utilice el DASHBOARD para identificar brechas, comparar componentes y definir prioridades del plan de cierre de brechas. | M23: Nivel 5 (100%) | N23: Predictivo
B24: 7. En Matriz Prioridades establezca las acciones a seguir considerando la factibilidad de las mismas.
B25: Nota: las preguntas sin respuesta se consideran pendientes y reducen el avance mostrado en el dashboard.
B27: CONTENIDO DEL LIBRO
B28: Instrucciones | C28: Registro inicial y guía de uso.
B29: Preguntas | C29: Cuestionario de 20 preguntas (5 por dimensiones) con evaluación de nivel de cumplimiento.
B30: Rúbrica de Evaluación | C30: Detalle de los criterios de evaluación por nivel de cumplimiento (0/25/50/75/100%).
B31: Escala | C31: Interpretación detallada de los cinco niveles de madurez, general y por componente.
B32: Listas Evaluación | C32: Listas de opciones de respuesta utilizadas en los desplegables del cuestionario.
Q33: SOPORTE GRÁFICO (cálculo automático - no editar)
B34: DASHBOARD DE MADUREZ EN GESTIÓN F&S | R34: 1 | S34: 2 | T34: 3 | U34: 4 | V34: 5
B35: COMPONENTE EVALUADO | D35: ¿APLICA? | E35: % | G35: CLASIFICACIÓN ESPECÍFICA POR COMPONENTE | J35: CUMPLIMIENTO GLOBAL | M35: RESPUESTAS REGISTRADAS | Q35: Dimensión | R35: =Escala!$I$21 -> Inicial / Reactivo | S35: =Escala!$I$22 -> Dependiente | T35: =Escala!$I$23 -> Independiente | U35: =Escala!$I$24 -> Interdependiente | V35: =Escala!$I$25 -> Predictivo | W35: % | X35: N° nivel | Y35: Nivel | Z35: Etiqueta
B36: D1. Gobernanza, organización y liderazgo | D36: Decidir | E36: =IF($D36="NO","No Aplica",IF(OR(COUNTIF(Preguntas!G5:G21,"EVA")>0,COUNTBLANK(Preguntas!G5:G21)>0),"EVA",AVERAGE(Preguntas!G5:G21))) -> EVA | G36: =IF(E36="No Aplica","No Aplica",IF(E36="EVA","POR EVALUAR",IF(E36<=39%,"Inicial / Reactivo",IF(E36<=59%,"Dependiente",IF(E36<=79%,"Independiente",IF(E36<=99%,"Interdependiente","Predictivo")))))) -> POR EVALUAR | J36: =IF(COUNTIF(E36:E47,"*eva*")>0,"EVALUAR",IF(COUNT(E36:E47)=0,"No Aplica",AVERAGE(E36:E47))) -> EVALUAR | M36: =(128-COUNTIF(Preguntas!$F$5:$F$132,"EVA"))&" / 128" -> 0 / 128 | Q36: =B36 -> D1. Gobernanza, organización y liderazgo | R36: =IF($X36=R$34,$W36,NA()) -> #N/A | S36: =IF($X36=S$34,$W36,NA()) -> #N/A | T36: =IF($X36=T$34,$W36,NA()) -> #N/A | U36: =IF($X36=U$34,$W36,NA()) -> #N/A | V36: =IF($X36=V$34,$W36,NA()) -> #N/A | W36: =E36 -> EVA | X36: =IF(ISNUMBER(W36),COUNTIF(Escala!$J$21:$J$24,"<"&W36)+1,"") | Y36: {=IF(X36="","",INDEX(Escala!$I$21:$I$25,X36))} | Z36: =IF(ISNUMBER(W36),TEXT(W36,"0%")&" | "&Y36,W36) -> EVA
B37: D.2 Gestión del riesgo de fatiga | D37: Decidir | E37: =IF($D37="NO","No Aplica",IF(OR(COUNTIF(Preguntas!G22:G32,"EVA")>0,COUNTBLANK(Preguntas!G22:G32)>0),"EVA",AVERAGE(Preguntas!G22:G32))) -> EVA | G37: =IF(E37="No Aplica","No Aplica",IF(E37="EVA","POR EVALUAR",IF(E37<=39%,"Inicial / Reactivo",IF(E37<=59%,"Dependiente",IF(E37<=79%,"Independiente",IF(E37<=99%,"Interdependiente","Predictivo")))))) -> POR EVALUAR | Q37: =B37 -> D.2 Gestión del riesgo de fatiga | R37: =IF($X37=R$34,$W37,NA()) -> #N/A | S37: =IF($X37=S$34,$W37,NA()) -> #N/A | T37: =IF($X37=T$34,$W37,NA()) -> #N/A | U37: =IF($X37=U$34,$W37,NA()) -> #N/A | V37: =IF($X37=V$34,$W37,NA()) -> #N/A | W37: =E37 -> EVA | X37: =IF(ISNUMBER(W37),COUNTIF(Escala!$J$21:$J$24,"<"&W37)+1,"") | Y37: {=IF(X37="","",INDEX(Escala!$I$21:$I$25,X37))} | Z37: =IF(ISNUMBER(W37),TEXT(W37,"0%")&" | "&Y37,W37) -> EVA
B38: D.3 Diseño de turnos y jornadas | D38: Decidir | E38: =IF($D38="NO","No Aplica",IF(OR(COUNTIF(Preguntas!G33:G43,"EVA")>0,COUNTBLANK(Preguntas!G33:G43)>0),"EVA",AVERAGE(Preguntas!G33:G43))) -> EVA | G38: =IF(E38="No Aplica","No Aplica",IF(E38="EVA","POR EVALUAR",IF(E38<=39%,"Inicial / Reactivo",IF(E38<=59%,"Dependiente",IF(E38<=79%,"Independiente",IF(E38<=99%,"Interdependiente","Predictivo")))))) -> POR EVALUAR | J38: DIMENSIONES APLICADAS | M38: NIVEL GENERAL | Q38: =B38 -> D.3 Diseño de turnos y jornadas | R38: =IF($X38=R$34,$W38,NA()) -> #N/A | S38: =IF($X38=S$34,$W38,NA()) -> #N/A | T38: =IF($X38=T$34,$W38,NA()) -> #N/A | U38: =IF($X38=U$34,$W38,NA()) -> #N/A | V38: =IF($X38=V$34,$W38,NA()) -> #N/A | W38: =E38 -> EVA | X38: =IF(ISNUMBER(W38),COUNTIF(Escala!$J$21:$J$24,"<"&W38)+1,"") | Y38: {=IF(X38="","",INDEX(Escala!$I$21:$I$25,X38))} | Z38: =IF(ISNUMBER(W38),TEXT(W38,"0%")&" | "&Y38,W38) -> EVA
B39: D.4 Gestión operacional de la fatiga | D39: Decidir | E39: =IF($D39="NO","No Aplica",IF(OR(COUNTIF(Preguntas!G44:G60,"EVA")>0,COUNTBLANK(Preguntas!G44:G60)>0),"EVA",AVERAGE(Preguntas!G44:G60))) -> EVA | G39: =IF(E39="No Aplica","No Aplica",IF(E39="EVA","POR EVALUAR",IF(E39<=39%,"Inicial / Reactivo",IF(E39<=59%,"Dependiente",IF(E39<=79%,"Independiente",IF(E39<=99%,"Interdependiente","Predictivo")))))) -> POR EVALUAR | J39: =(12-COUNTIF(D36:D47,"NO"))&" / 12" -> 12 / 12 | M39: =IF(COUNT($E$36:$E$47)<MIN(4,COUNTIF($D$36:$D$47,"<>NO")),"POR EVALUAR",IF(COUNT($E$36:$E$47)=0,"No Aplica",IF(AVERAGE($E$36:$E$47)<=39%,"Inicial / Reactivo",IF(AVERAGE($E$36:$E$47)<=59%,"Dependiente",IF(AVERAGE($E$36:$E$47)<=79%,"Independiente",IF(AVERAGE($E$36:$E$47)<=99%,"Interdependiente","Predictivo")))))) -> POR EVALUAR | Q39: =B39 -> D.4 Gestión operacional de la fatiga | R39: =IF($X39=R$34,$W39,NA()) -> #N/A | S39: =IF($X39=S$34,$W39,NA()) -> #N/A | T39: =IF($X39=T$34,$W39,NA()) -> #N/A | U39: =IF($X39=U$34,$W39,NA()) -> #N/A | V39: =IF($X39=V$34,$W39,NA()) -> #N/A | W39: =E39 -> EVA | X39: =IF(ISNUMBER(W39),COUNTIF(Escala!$J$21:$J$24,"<"&W39)+1,"") | Y39: {=IF(X39="","",INDEX(Escala!$I$21:$I$25,X39))} | Z39: =IF(ISNUMBER(W39),TEXT(W39,"0%")&" | "&Y39,W39) -> EVA
B40: D.5 Gestión de la somnolencia | D40: Decidir | E40: =IF($D40="NO","No Aplica",IF(OR(COUNTIF(Preguntas!G61:G72,"EVA")>0,COUNTBLANK(Preguntas!G61:G72)>0),"EVA",AVERAGE(Preguntas!G61:G72))) -> EVA | G40: =IF(E40="No Aplica","No Aplica",IF(E40="EVA","POR EVALUAR",IF(E40<=39%,"Inicial / Reactivo",IF(E40<=59%,"Dependiente",IF(E40<=79%,"Independiente",IF(E40<=99%,"Interdependiente","Predictivo")))))) -> POR EVALUAR | Q40: =B40 -> D.5 Gestión de la somnolencia | R40: =IF($X40=R$34,$W40,NA()) -> #N/A | S40: =IF($X40=S$34,$W40,NA()) -> #N/A | T40: =IF($X40=T$34,$W40,NA()) -> #N/A | U40: =IF($X40=U$34,$W40,NA()) -> #N/A | V40: =IF($X40=V$34,$W40,NA()) -> #N/A | W40: =E40 -> EVA | X40: =IF(ISNUMBER(W40),COUNTIF(Escala!$J$21:$J$24,"<"&W40)+1,"") | Y40: {=IF(X40="","",INDEX(Escala!$I$21:$I$25,X40))} | Z40: =IF(ISNUMBER(W40),TEXT(W40,"0%")&" | "&Y40,W40) -> EVA
B41: D.6 Salud ocupacional y trastornos del sueño | D41: Decidir | E41: =IF($D41="NO","No Aplica",IF(OR(COUNTIF(Preguntas!G73:G78,"EVA")>0,COUNTBLANK(Preguntas!G73:G78)>0),"EVA",AVERAGE(Preguntas!G73:G78))) -> EVA | G41: =IF(E41="No Aplica","No Aplica",IF(E41="EVA","POR EVALUAR",IF(E41<=39%,"Inicial / Reactivo",IF(E41<=59%,"Dependiente",IF(E41<=79%,"Independiente",IF(E41<=99%,"Interdependiente","Predictivo")))))) -> POR EVALUAR | J41: LECTURA RÁPIDA | Q41: =B41 -> D.6 Salud ocupacional y trastornos del sueño | R41: =IF($X41=R$34,$W41,NA()) -> #N/A | S41: =IF($X41=S$34,$W41,NA()) -> #N/A | T41: =IF($X41=T$34,$W41,NA()) -> #N/A | U41: =IF($X41=U$34,$W41,NA()) -> #N/A | V41: =IF($X41=V$34,$W41,NA()) -> #N/A | W41: =E41 -> EVA | X41: =IF(ISNUMBER(W41),COUNTIF(Escala!$J$21:$J$24,"<"&W41)+1,"") | Y41: {=IF(X41="","",INDEX(Escala!$I$21:$I$25,X41))} | Z41: =IF(ISNUMBER(W41),TEXT(W41,"0%")&" | "&Y41,W41) -> EVA
B42: D.7 Controles críticos | D42: Decidir | E42: =IF($D42="NO","No Aplica",IF(OR(COUNTIF(Preguntas!G79:G86,"EVA")>0,COUNTBLANK(Preguntas!G79:G86)>0),"EVA",AVERAGE(Preguntas!G79:G86))) -> EVA | G42: =IF(E42="No Aplica","No Aplica",IF(E42="EVA","POR EVALUAR",IF(E42<=39%,"Inicial / Reactivo",IF(E42<=59%,"Dependiente",IF(E42<=79%,"Independiente",IF(E42<=99%,"Interdependiente","Predictivo")))))) -> POR EVALUAR | J42: =IF((20-COUNTIF(Preguntas!$F$5:$F$119,"EVA"))<20,"Evaluación en curso: se han registrado "&(20-COUNTIF(Preguntas!$F$5:$F$119,"EVA"))&" de 20 respuestas. Complete las preguntas pendientes para consolidar el diagnóstico.","La evaluación presenta un cumplimiento global de "&TEXT(AVERAGE($E$36:$E$47),"0%")&". El componente más sólido es "&INDEX($B$36:$B$47,MATCH(MAX($E$36:$E$47),$E$36:$E$47,0))&" y la principal brecha está en "&INDEX($B$36:$B$47,MATCH(MIN($E$36:$E$47),$E$36:$E$47,0))&".") -> Evaluación en curso: se han registrado -95 de 20 respuestas. Complete las preguntas pendientes para consolidar el diagnóstico. | Q42: =B42 -> D.7 Controles críticos | R42: =IF($X42=R$34,$W42,NA()) -> #N/A | S42: =IF($X42=S$34,$W42,NA()) -> #N/A | T42: =IF($X42=T$34,$W42,NA()) -> #N/A | U42: =IF($X42=U$34,$W42,NA()) -> #N/A | V42: =IF($X42=V$34,$W42,NA()) -> #N/A | W42: =E42 -> EVA | X42: =IF(ISNUMBER(W42),COUNTIF(Escala!$J$21:$J$24,"<"&W42)+1,"") | Y42: {=IF(X42="","",INDEX(Escala!$I$21:$I$25,X42))} | Z42: =IF(ISNUMBER(W42),TEXT(W42,"0%")&" | "&Y42,W42) -> EVA
B43: D.8 Tecnología y sistemas de monitoreo | D43: Decidir | E43: =IF($D43="NO","No Aplica",IF(OR(COUNTIF(Preguntas!G87:G93,"EVA")>0,COUNTBLANK(Preguntas!G87:G93)>0),"EVA",AVERAGE(Preguntas!G87:G93))) -> EVA | G43: =IF(E43="No Aplica","No Aplica",IF(E43="EVA","POR EVALUAR",IF(E43<=39%,"Inicial / Reactivo",IF(E43<=59%,"Dependiente",IF(E43<=79%,"Independiente",IF(E43<=99%,"Interdependiente","Predictivo")))))) -> POR EVALUAR | Q43: =B43 -> D.8 Tecnología y sistemas de monitoreo | R43: =IF($X43=R$34,$W43,NA()) -> #N/A | S43: =IF($X43=S$34,$W43,NA()) -> #N/A | T43: =IF($X43=T$34,$W43,NA()) -> #N/A | U43: =IF($X43=U$34,$W43,NA()) -> #N/A | V43: =IF($X43=V$34,$W43,NA()) -> #N/A | W43: =E43 -> EVA | X43: =IF(ISNUMBER(W43),COUNTIF(Escala!$J$21:$J$24,"<"&W43)+1,"") | Y43: {=IF(X43="","",INDEX(Escala!$I$21:$I$25,X43))} | Z43: =IF(ISNUMBER(W43),TEXT(W43,"0%")&" | "&Y43,W43) -> EVA
B44: D.9 Factores humanos y organizacionales | D44: Decidir | E44: =IF($D44="NO","No Aplica",IF(OR(COUNTIF(Preguntas!G94:G98,"EVA")>0,COUNTBLANK(Preguntas!G94:G98)>0),"EVA",AVERAGE(Preguntas!G94:G98))) -> EVA | G44: =IF(E44="No Aplica","No Aplica",IF(E44="EVA","POR EVALUAR",IF(E44<=39%,"Inicial / Reactivo",IF(E44<=59%,"Dependiente",IF(E44<=79%,"Independiente",IF(E44<=99%,"Interdependiente","Predictivo")))))) -> POR EVALUAR | J44: PRIORIDAD GENERAL SUGERIDA | Q44: =B44 -> D.9 Factores humanos y organizacionales | R44: =IF($X44=R$34,$W44,NA()) -> #N/A | S44: =IF($X44=S$34,$W44,NA()) -> #N/A | T44: =IF($X44=T$34,$W44,NA()) -> #N/A | U44: =IF($X44=U$34,$W44,NA()) -> #N/A | V44: =IF($X44=V$34,$W44,NA()) -> #N/A | W44: =E44 -> EVA | X44: =IF(ISNUMBER(W44),COUNTIF(Escala!$J$21:$J$24,"<"&W44)+1,"") | Y44: {=IF(X44="","",INDEX(Escala!$I$21:$I$25,X44))} | Z44: =IF(ISNUMBER(W44),TEXT(W44,"0%")&" | "&Y44,W44) -> EVA
B45: D.10 Cultura de seguridad observable | D45: Decidir | E45: =IF($D45="NO","No Aplica",IF(OR(COUNTIF(Preguntas!G99:G111,"EVA")>0,COUNTBLANK(Preguntas!G99:G111)>0),"EVA",AVERAGE(Preguntas!G99:G111))) -> EVA | G45: =IF(E45="No Aplica","No Aplica",IF(E45="EVA","POR EVALUAR",IF(E45<=39%,"Inicial / Reactivo",IF(E45<=59%,"Dependiente",IF(E45<=79%,"Independiente",IF(E45<=99%,"Interdependiente","Predictivo")))))) -> POR EVALUAR | J45: =IF((20-COUNTIF(Preguntas!$F$5:$F$119,"EVA"))<20,"Finalice primero las respuestas pendientes; los resultados actuales son preliminares.",IF(MAX($E$36:$E$47)=MIN($E$36:$E$47),"Todos los componentes tienen el mismo resultado ("&TEXT(AVERAGE($E$36:$E$47),"0%")&").",INDEX($B$36:$B$47,MATCH(MIN($E$36:$E$47),$E$36:$E$47,0))&" registra el menor cumplimiento ("&TEXT(MIN($E$36:$E$47),"0%")&"). Priorice un plan de acción para este componente.")) -> Finalice primero las respuestas pendientes; los resultados actuales son preliminares. | Q45: =B45 -> D.10 Cultura de seguridad observable | R45: =IF($X45=R$34,$W45,NA()) -> #N/A | S45: =IF($X45=S$34,$W45,NA()) -> #N/A | T45: =IF($X45=T$34,$W45,NA()) -> #N/A | U45: =IF($X45=U$34,$W45,NA()) -> #N/A | V45: =IF($X45=V$34,$W45,NA()) -> #N/A | W45: =E45 -> EVA | X45: =IF(ISNUMBER(W45),COUNTIF(Escala!$J$21:$J$24,"<"&W45)+1,"") | Y45: {=IF(X45="","",INDEX(Escala!$I$21:$I$25,X45))} | Z45: =IF(ISNUMBER(W45),TEXT(W45,"0%")&" | "&Y45,W45) -> EVA
B46: D.11 Factores preventivos | D46: Decidir | E46: =IF($D46="NO","No Aplica",IF(OR(COUNTIF(Preguntas!G112:G119,"EVA")>0,COUNTBLANK(Preguntas!G112:G119)>0),"EVA",AVERAGE(Preguntas!G112:G119))) -> EVA | G46: =IF(E46="No Aplica","No Aplica",IF(E46="EVA","POR EVALUAR",IF(E46<=39%,"Inicial / Reactivo",IF(E46<=59%,"Dependiente",IF(E46<=79%,"Independiente",IF(E46<=99%,"Interdependiente","Predictivo")))))) -> POR EVALUAR | Q46: =B46 -> D.11 Factores preventivos | R46: =IF($X46=R$34,$W46,NA()) -> #N/A | S46: =IF($X46=S$34,$W46,NA()) -> #N/A | T46: =IF($X46=T$34,$W46,NA()) -> #N/A | U46: =IF($X46=U$34,$W46,NA()) -> #N/A | V46: =IF($X46=V$34,$W46,NA()) -> #N/A | W46: =E46 -> EVA | X46: =IF(ISNUMBER(W46),COUNTIF(Escala!$J$21:$J$24,"<"&W46)+1,"") | Y46: {=IF(X46="","",INDEX(Escala!$I$21:$I$25,X46))} | Z46: =IF(ISNUMBER(W46),TEXT(W46,"0%")&" | "&Y46,W46) -> EVA
B47: D.12 Factores correctivos | D47: Decidir | E47: =IF($D47="NO","No Aplica",IF(OR(COUNTIF(Preguntas!G120:G132,"EVA")>0,COUNTBLANK(Preguntas!G120:G132)>0),"EVA",AVERAGE(Preguntas!G120:G132))) -> EVA | G47: =IF(E47="No Aplica","No Aplica",IF(E47="EVA","POR EVALUAR",IF(E47<=39%,"Inicial / Reactivo",IF(E47<=59%,"Dependiente",IF(E47<=79%,"Independiente",IF(E47<=99%,"Interdependiente","Predictivo")))))) -> POR EVALUAR | Q47: =B47 -> D.12 Factores correctivos | R47: =IF($X47=R$34,$W47,NA()) -> #N/A | S47: =IF($X47=S$34,$W47,NA()) -> #N/A | T47: =IF($X47=T$34,$W47,NA()) -> #N/A | U47: =IF($X47=U$34,$W47,NA()) -> #N/A | V47: =IF($X47=V$34,$W47,NA()) -> #N/A | W47: =E47 -> EVA | X47: =IF(ISNUMBER(W47),COUNTIF(Escala!$J$21:$J$24,"<"&W47)+1,"") | Y47: {=IF(X47="","",INDEX(Escala!$I$21:$I$25,X47))} | Z47: =IF(ISNUMBER(W47),TEXT(W47,"0%")&" | "&Y47,W47) -> EVA
...

Sheet Preguntas
B2: PREGUNTAS POR DIMENSIONES
B4: DIMENSIÓN | C4: PREGUNTAS | D4: Tipo de evidencia | E4: EVIDENCIA OBSERVADA/ENTREVISTA | F4: NIVEL DE CUMPLIMIENTO | G4: % LOGRADO
B5: D1. Gobernanza, organización y liderazgo | C5: ¿En qué medida están definidas las responsabilidades frente a los riesgos críticos (incluidas la fatiga y la somnolencia) para cada nivel: gerencia, superintendencia, supervisión, despacho, trabajadores y contratistas, incluida la autoridad para detener una tarea o retirar a una persona? | D5: Documental | F5: EVA | G5: =IF(F5="EVA","EVA",IFERROR((MATCH(F5,'Listas Evaluación'!A1:F1,0)-2)/4,"")) -> EVA
C6: ¿En qué medida las personas de distintos niveles describen correctamente qué les corresponde hacer frente a un riesgo crítico, por ejemplo ante un trabajador con signos de fatiga o somnolencia? | D6: Entrevista | F6: EVA | G6: =IF(F6="EVA","EVA",IFERROR((MATCH(F6,'Listas Evaluación'!A2:F2,0)-2)/4,"")) -> EVA
C7: ¿En qué medida el desempeño en seguridad de los responsables se revisa y tiene consecuencias en la práctica (reconocimiento, corrección, apoyo), y no solo el desempeño productivo? | D7: Registro | F7: EVA | G7: =IF(F7="EVA","EVA",IFERROR((MATCH(F7,'Listas Evaluación'!A3:F3,0)-2)/4,"")) -> EVA
C8: ¿En qué medida la alta dirección demuestra con acciones concretas su compromiso con la gestión de los riesgos críticos (presencia en terreno, asignación de recursos, participación en revisiones, decisiones que priorizan la seguridad)? | D8: Registro | F8: EVA | G8: =IF(F8="EVA","EVA",IFERROR((MATCH(F8,'Listas Evaluación'!A4:F4,0)-2)/4,"")) -> EVA
C9: ¿En qué medida supervisores y jefaturas realizan acciones concretas y visibles de seguridad durante el turno (conversaciones de riesgo, verificación de controles, detención de trabajos inseguros, atención a la fatiga del equipo), incluido el turno de noche? | D9: Observación en terreno | F9: EVA | G9: =IF(F9="EVA","EVA",IFERROR((MATCH(F9,'Listas Evaluación'!A5:F5,0)-2)/4,"")) -> EVA
C10: ¿En qué medida la organización tiene objetivos claros y verificables para sus riesgos críticos, incluidas la fatiga y la somnolencia, y la línea de mando los conoce? | D10: Documental | F10: EVA | G10: =IF(F10="EVA","EVA",IFERROR((MATCH(F10,'Listas Evaluación'!A6:F6,0)-2)/4,"")) -> EVA
C11: ¿En qué medida existen instancias o criterios para tomar decisiones operacionales (cambios de turno, extensiones de jornada, programación de tareas críticas, metas de producción) considerando explícitamente los riesgos críticos? | D11: Documental | F11: EVA | G11: =IF(F11="EVA","EVA",IFERROR((MATCH(F11,'Listas Evaluación'!A7:F7,0)-2)/4,"")) -> EVA
C12: ¿En qué medida la planificación diaria, semanal y de proyectos (por ejemplo, paradas de planta) incorpora en la práctica la dotación, los turnos y el control de la fatiga antes de comprometer metas o plazos? | D12: Registro | F12: EVA | G12: =IF(F12="EVA","EVA",IFERROR((MATCH(F12,'Listas Evaluación'!A8:F8,0)-2)/4,"")) -> EVA
C13: ¿En qué medida la dirección revisa periódicamente información sobre fatiga y riesgos críticos (exposición, alertas, eventos, desviaciones) y deja decisiones con responsable? | D13: Registro | F13: EVA | G13: =IF(F13="EVA","EVA",IFERROR((MATCH(F13,'Listas Evaluación'!A9:F9,0)-2)/4,"")) -> EVA
C14: ¿En qué medida las decisiones tomadas sobre riesgos críticos se implementaron y muestran efecto en los resultados asociados (por ejemplo, menos turnos fuera de límite)? | D14: Análisis de tendencia | F14: EVA | G14: =IF(F14="EVA","EVA",IFERROR((MATCH(F14,'Listas Evaluación'!A10:F10,0)-2)/4,"")) -> EVA
C15: ¿En qué medida los recursos necesarios para controlar la fatiga (relevos, tecnología, apoyo de salud) están disponibles en todos los turnos y no solo en el turno de día? | D15: Registro | F15: EVA | G15: =IF(F15="EVA","EVA",IFERROR((MATCH(F15,'Listas Evaluación'!A11:F11,0)-2)/4,"")) -> EVA
C16: ¿En qué medida la información sobre riesgos fluye en ambos sentidos entre la dirección, la supervisión y los trabajadores, y las preocupaciones planteadas reciben respuesta? | D16: Entrevista | F16: EVA | G16: =IF(F16="EVA","EVA",IFERROR((MATCH(F16,'Listas Evaluación'!A12:F12,0)-2)/4,"")) -> EVA
C17: ¿En qué medida los trabajadores tienen y usan formas reales de participar y plantear preocupaciones sobre los riesgos (comités, reuniones, canales directos, participación en el diseño de turnos o tareas)? | D17: Registro | F17: EVA | G17: =IF(F17="EVA","EVA",IFERROR((MATCH(F17,'Listas Evaluación'!A13:F13,0)-2)/4,"")) -> EVA
... C21: ¿En qué medida se verifica con datos (control de acceso, registros de turnos) que los contratistas cumplen los límites de jornada y descanso? | D21: Datos de sistema | F21: EVA | G21: =IF(F21="EVA","EVA",IFERROR((MATCH(F21,'Listas Evaluación'!A17:F17,0)-2)/4,"")) -> EVA
B22: D.2 Gestión del riesgo de fatiga | C22: ¿En qué medida la organización sabe qué tareas y cargos son sensibles a la fatiga o la somnolencia (equipos móviles, aislamiento, izaje, conducción, operación de planta) y cuántas personas están expuestas en cada turno? | D22: Documental | F22: EVA | G22: =IF(F22="EVA","EVA",IFERROR((MATCH(F22,'Listas Evaluación'!A18:F18,0)-2)/4,"")) -> EVA
C23: ¿En qué medida esa identificación se usa para decidir quién requiere evaluación antes del turno o monitoreo, y coincide con la dotación real? | D23: Datos de sistema | F23: EVA | G23: =IF(F23="EVA","EVA",IFERROR((MATCH(F23,'Listas Evaluación'!A19:F19,0)-2)/4,"")) -> EVA
C24: ¿En qué medida el análisis de riesgo distingue las causas de fatiga (carga, duración de la tarea, recuperación) de las causas de somnolencia (deuda de sueño, ventana circadiana, trastornos del sueño) e identifica las barreras críticas y sus responsables (por ejemplo, con un bow-tie)? | D24: Documental | F24: EVA | G24: =IF(F24="EVA","EVA",IFERROR((MATCH(F24,'Listas Evaluación'!A20:F20,0)-2)/4,"")) -> EVA
C25: ¿En qué medida el análisis de riesgo se revisó en terreno con operadores y supervisores en los últimos 12 meses y se actualiza después de incidentes o cambios? | D25: Registro | F25: EVA | G25: =IF(F25="EVA","EVA",IFERROR((MATCH(F25,'Listas Evaluación'!A21:F21,0)-2)/4,"")) -> EVA
C26: ¿En qué medida la estimación del riesgo que queda de fatiga se apoya en datos de exposición y de funcionamiento de los controles, y no solo en juicio experto, y muestra su evolución? | D26: Análisis de tendencia | F26: EVA | G26: =IF(F26="EVA","EVA",IFERROR((MATCH(F26,'Listas Evaluación'!A22:F22,0)-2)/4,"")) -> EVA
C27: ¿En qué medida los cambios de roster, dotación, flota, rutas o proyectos (por ejemplo, paradas de planta) se evalúan considerando su efecto en la fatiga y la somnolencia antes de aplicarlos? | D27: Documental | F27: EVA | G27: =IF(F27="EVA","EVA",IFERROR((MATCH(F27,'Listas Evaluación'!A23:F23,0)-2)/4,"")) -> EVA
C28: En los cambios relevantes de los últimos 12 meses (incluidas paradas de planta), ¿en qué medida se evaluó la fatiga antes de implementarlos? | D28: Registro | F28: EVA | G28: =IF(F28="EVA","EVA",IFERROR((MATCH(F28,'Listas Evaluación'!A24:F24,0)-2)/4,"")) -> EVA
C29: Durante paradas de planta, contingencias, ausentismo alto o emergencias, ¿en qué medida se mantienen los límites de jornada y los controles críticos, o se aplican excepciones autorizadas con controles compensatorios verificados? | D29: Datos de sistema | F29: EVA | G29: =IF(F29="EVA","EVA",IFERROR((MATCH(F29,'Listas Evaluación'!A25:F25,0)-2)/4,"")) -> EVA
C30: ¿En qué medida la forma de investigar incidentes exige considerar la fatiga y la somnolencia con datos objetivos (horas despierto, sueño en 24 y 48 h, hora del evento respecto a la ventana circadiana, duración del turno, alertas previas)? | D30: Documental | F30: EVA | G30: =IF(F30="EVA","EVA",IFERROR((MATCH(F30,'Listas Evaluación'!A26:F26,0)-2)/4,"")) -> EVA
C31: En las investigaciones de incidentes de alto potencial de los últimos 12 meses, ¿en qué medida se evaluó la fatiga con esos datos y se buscaron causas del sistema, no solo la conducta individual? | D31: Registro | F31: EVA | G31: =IF(F31="EVA","EVA",IFERROR((MATCH(F31,'Listas Evaluación'!A27:F27,0)-2)/4,"")) -> EVA
C32: ¿En qué medida las acciones derivadas de investigaciones con factor fatiga resultaron efectivas, sin repetición del mismo tipo de falla en los 6 meses siguientes? | D32: Análisis de tendencia | F32: EVA | G32: =IF(F32="EVA","EVA",IFERROR((MATCH(F32,'Listas Evaluación'!A28:F28,0)-2)/4,"")) -> EVA
B33: D.3 Diseño de turnos y jornadas | C33: ¿En qué medida los sistemas de turno se diseñan con criterios explícitos de fatiga (duración máxima, noches consecutivas, rotación, descanso entre ciclos, oportunidad de sueño) y con un método de evaluación declarado? | D33: Documental | F33: EVA | G33: =IF(F33="EVA","EVA",IFERROR((MATCH(F33,'Listas Evaluación'!A29:F29,0)-2)/4,"")) -> EVA
C34: ¿En qué medida los rosters programados en todas las áreas expuestas respetan esos criterios? | D34: Datos de sistema | F34: EVA | G34: =IF(F34="EVA","EVA",IFERROR((MATCH(F34,'Listas Evaluación'!A30:F30,0)-2)/4,"")) -> EVA
C35: ¿En qué medida los turnos realmente trabajados (control de acceso o asistencia) coinciden con los programados y respetan los límites, sin desviaciones repetidas? | D35: Datos de sistema | F35: EVA | G35: =IF(F35="EVA","EVA",IFERROR((MATCH(F35,'Listas Evaluación'!A31:F31,0)-2)/4,"")) -> EVA
C36: ¿En qué medida se analiza la relación entre el diseño del roster (noche 1 frente a noche 4, horas en ventana circadiana) y las alertas de somnolencia, y se ajusta el roster con efecto medido cuando aparecen patrones? | D36: Análisis de tendencia | F36: EVA | G36: =IF(F36="EVA","EVA",IFERROR((MATCH(F36,'Listas Evaluación'!A32:F32,0)-2)/4,"")) -> EVA
C37: ¿En qué medida los trabajadores expuestos participan en el diseño y la revisión de los sistemas de turno (consultas, comités, pilotos)? | D37: Registro | F37: EVA | G37: =IF(F37="EVA","EVA",IFERROR((MATCH(F37,'Listas Evaluación'!A33:F33,0)-2)/4,"")) -> EVA
C38: ¿En qué medida hay límites claros de horas extra, extensión de turno, llamados y horas máximas por período, con autorización escalonada y controles compensatorios? | D38: Documental | F38: EVA | G38: =IF(F38="EVA","EVA",IFERROR((MATCH(F38,'Listas Evaluación'!A34:F34,0)-2)/4,"")) -> EVA
C39: ¿En qué medida las extensiones de jornada sobre el límite se autorizan antes de ocurrir y se acompañan de controles compensatorios (evaluación de aptitud, restricción de tareas)? | D39: Registro | F39: EVA | G39: =IF(F39="EVA","EVA",IFERROR((MATCH(F39,'Listas Evaluación'!A35:F35,0)-2)/4,"")) -> EVA
C40: ¿En qué medida existe un seguimiento, idealmente automático, que avise a la supervisión cuando una persona se acerca o supera los límites de horas, con evidencia de que se actúa? | D40: Datos de sistema | F40: EVA | G40: =IF(F40="EVA","EVA",IFERROR((MATCH(F40,'Listas Evaluación'!A36:F36,0)-2)/4,"")) -> EVA
C41: ¿En qué medida se evaluó el riesgo del traslado después del turno (distancia, duración, conducción propia o bus, salida de turno de noche) y se definieron controles (transporte provisto, pausas, no conducir tras turno de noche)? | D41: Documental | F41: EVA | G41: =IF(F41="EVA","EVA",IFERROR((MATCH(F41,'Listas Evaluación'!A37:F37,0)-2)/4,"")) -> EVA
C42: ¿En qué medida los controles de traslado se aplican en la práctica (por ejemplo, % de trabajadores de turno de noche que usan el transporte provisto, conductores de bus evaluados)? | D42: Observación en terreno | F42: EVA | G42: =IF(F42="EVA","EVA",IFERROR((MATCH(F42,'Listas Evaluación'!A38:F38,0)-2)/4,"")) -> EVA
C43: ¿En qué medida se cumple en la programación real un descanso mínimo entre turnos, descontando traslado y alimentación? | D43: Datos de sistema | F43: EVA | G43: =IF(F43="EVA","EVA",IFERROR((MATCH(F43,'Listas Evaluación'!A39:F39,0)-2)/4,"")) -> EVA
B44: D.4 Gestión operacional de la fatiga | C44: ¿En qué medida la evaluación de aptitud antes del turno usa preguntas o mediciones objetivas (horas de sueño en 24 y 48 h, horas despierto, síntomas), umbrales de decisión y acciones definidas (apto, apto con restricción, no apto)? | D44: Documental | F44: EVA | G44: =IF(F44="EVA","EVA",IFERROR((MATCH(F44,'Listas Evaluación'!A40:F40,0)-2)/4,"")) -> EVA
C45: ¿En qué medida la evaluación antes del turno se aplica a todo el personal en tareas críticas, en todos los turnos (incluidas noches y fines de semana) y a contratistas? | D45: Registro | F45: EVA | G45: =IF(F45="EVA","EVA",IFERROR((MATCH(F45,'Listas Evaluación'!A41:F41,0)-2)/4,"")) -> EVA
...

Sheet Rúbrica de Evaluación
B1: N° | C1: Dimensión | D1: Subdimensión | E1: Cód. sub | F1: Foco | G1: Punto de la cadena causal | H1: Riesgo | I1: Evento no deseado | J1: Control | K1: Propósito del control | L1: Criterio | M1: N° Preg. | N1: Pregunta | O1: Evidencia posible (ejemplos) | P1: Criterio 0% | Q1: Criterio 25% | R1: Criterio 50% | S1: Criterio 75% | T1: Criterio 100% | U1: Nivel de evaluación | V1: Tipo de evidencia | W1: Método de evaluación | X1: Consecuencia potencial | Y1: Tipo de control
B2: 1 | C2: D1. Gobernanza, organización y liderazgo | D2: Responsabilidades, roles y rendición de cuentas | E2: S01.1 | F2: Ambos | G2: Degradación de barreras | H2: Fatiga y/o somnolencia en persona expuesta a tarea crítica | I2: Persona fatigada o somnolienta permanece en tarea crítica sin ser detectada ni intervenida | J2: Responsabilidades frente a los riesgos críticos definidas, comprendidas y exigidas | K2: Que cada nivel sepa qué le corresponde frente a los riesgos críticos y responda por ello | L2: Responsabilidades de seguridad definidas por nivel | M2: 1 | N2: ¿En qué medida están definidas las responsabilidades frente a los riesgos críticos (incluidas la fatiga y la somnolencia) para cada nivel: gerencia, superintendencia, supervisión, despacho, trabajadores y contratistas, incluida la autoridad para detener una tarea o retirar a una persona? | O2: Ejemplos: descripciones de cargo, matrices de responsabilidades o instrucciones escritas; si no hay documentos, lo que declaran los responsables y lo que se observa | P2: El criterio «Responsabilidades de seguridad definidas por nivel» no está definido ni documentado; no existen criterios operativos, responsables ni evidencia aplicable. | Q2: El criterio «Responsabilidades de seguridad definidas por nivel» se aborda de manera informal o mediante documentos aislados, incompletos o desactualizados, sin alcance ni responsables claros. | R2: El criterio «Responsabilidades de seguridad definidas por nivel» está formalmente definido, pero cubre solo parte del alcance o presenta brechas relevantes de actualización, criterios, responsables o aprobación. | S2: El criterio «Responsabilidades de seguridad definidas por nivel» está definido, documentado, aprobado y vigente para la mayor parte del alcance; solo quedan brechas menores de cobertura o integración. | T2: El criterio «Responsabilidades de seguridad definidas por nivel» está completamente formalizado, aprobado, vigente e integrado a la gestión, con alcance, parámetros, responsables y revisión periódica verificables mediante revisión documental y entrevista. | U2: Design | V2: Documental | W2: Revisión documental y entrevista | X2: Grave | Y2: Administrativo
B3: 2 | D3: Responsabilidades, roles y rendición de cuentas | E3: S01.1 | F3: Ambos | G3: Degradación de barreras | H3: Fatiga y/o somnolencia en persona expuesta a tarea crítica | I3: Persona fatigada o somnolienta permanece en tarea crítica sin ser detectada ni intervenida | J3: Responsabilidades frente a los riesgos críticos definidas, comprendidas y exigidas | K3: Que cada nivel sepa qué le corresponde frente a los riesgos críticos y responda por ello | L3: Roles comprendidos en todos los niveles | M3: 2 | N3: ¿En qué medida las personas de distintos niveles describen correctamente qué les corresponde hacer frente a un riesgo crítico, por ejemplo ante un trabajador con signos de fatiga o somnolencia? | O3: Ejemplos: entrevistas breves a una muestra por nivel y turno (jefatura, supervisor, despachador, operador, contratista), comparando su respuesta con lo esperado | P3: El criterio «Roles comprendidos en todos los niveles» no se aplica en la práctica y no existe evidencia de implementación. | Q3: El criterio «Roles comprendidos en todos los niveles» se aplica solo en casos aislados o de manera informal, sin cobertura planificada ni consistencia entre áreas, turnos o personas expuestas. | R3: El criterio «Roles comprendidos en todos los niveles» está implementado parcialmente; alcanza parte de la población o del proceso, con brechas relevantes de cobertura, frecuencia o registro. | S3: El criterio «Roles comprendidos en todos los niveles» está implementado de forma regular en la mayor parte del alcance y con evidencia suficiente; persisten brechas menores de cobertura o consistencia. | T3: El criterio «Roles comprendidos en todos los niveles» está implementado sistemáticamente en todo el alcance aplicable, incluidos turnos y contratistas cuando corresponde, con registros completos y verificación mediante entrevista estructurada. | U3: Implementation | V3: Entrevista | W3: Entrevista estructurada | X3: Grave | Y3: Soporte
B4: 3 | D4: Responsabilidades, roles y rendición de cuentas | E4: S01.1 | F4: Ambos | G4: Degradación de barreras | H4: Fatiga y/o somnolencia en persona expuesta a tarea crítica | I4: Persona fatigada o somnolienta permanece en tarea crítica sin ser detectada ni intervenida | J4: Responsabilidades frente a los riesgos críticos definidas, comprendidas y exigidas | K4: Que cada nivel sepa qué le corresponde frente a los riesgos críticos y responda por ello | L4: Rendición de cuentas aplicada | M4: 3 | N4: ¿En qué medida el desempeño en seguridad de los responsables se revisa y tiene consecuencias en la práctica (reconocimiento, corrección, apoyo), y no solo el desempeño productivo? | O4: Ejemplos: evaluaciones de desempeño, revisiones de gestión, casos concretos en que se pidió cuenta por un incumplimiento o se reconoció una buena práctica | P4: El control asociado a «Rendición de cuentas aplicada» no opera en la práctica o, cuando se requiere, no genera la acción esperada. | Q4: El control asociado a «Rendición de cuentas aplicada» opera de forma esporádica y reactiva, depende de iniciativas individuales y carece de respuesta oportuna o registros consistentes. | R4: El control asociado a «Rendición de cuentas aplicada» funciona parcialmente o de manera irregular; genera algunas acciones, pero presenta brechas relevantes de oportunidad, calidad, seguimiento o trazabilidad. | S4: El control asociado a «Rendición de cuentas aplicada» funciona regularmente y genera la respuesta esperada en la mayoría de los casos; quedan desviaciones menores de oportunidad, cobertura o registro. | T4: El control asociado a «Rendición de cuentas aplicada» funciona de manera confiable, oportuna y consistente en todos los casos aplicables, con acciones trazables, seguimiento y evidencia verificable mediante reconstrucción de casos. | U4: Functioning | V4: Registro | W4: Reconstrucción de casos | X4: Grave | Y4: Administrativo
B5: 4 | D5: Compromiso visible de la dirección y de los líderes | E5: S01.2 | F5: Ambos | G5: Exposición | H5: Fatiga y/o somnolencia en persona expuesta a tarea crítica | I5: Persona fatigada o somnolienta permanece en tarea crítica sin ser detectada ni intervenida | J5: Liderazgo visible en seguridad | K5: Que la dirección y los líderes demuestren con acciones, no solo con declaraciones, que los riesgos críticos son prioridad | L5: Compromiso visible de la alta dirección | M5: 4 | N5: ¿En qué medida la alta dirección demuestra con acciones concretas su compromiso con la gestión de los riesgos críticos (presencia en terreno, asignación de recursos, participación en revisiones, decisiones que priorizan la seguridad)? | O5: Ejemplos: agenda de visitas a terreno, decisiones de recursos, actas o correos con decisiones; relato de trabajadores sobre la presencia de la dirección | P5: El criterio «Compromiso visible de la alta dirección» no se aplica en la práctica y no existe evidencia de implementación. | Q5: El criterio «Compromiso visible de la alta dirección» se aplica solo en casos aislados o de manera informal, sin cobertura planificada ni consistencia entre áreas, turnos o personas expuestas. | R5: El criterio «Compromiso visible de la alta dirección» está implementado parcialmente; alcanza parte de la población o del proceso, con brechas relevantes de cobertura, frecuencia o registro. | S5: El criterio «Compromiso visible de la alta dirección» está implementado de forma regular en la mayor parte del alcance y con evidencia suficiente; persisten brechas menores de cobertura o consistencia. | T5: El criterio «Compromiso visible de la alta dirección» está implementado sistemáticamente en todo el alcance aplicable, incluidos turnos y contratistas cuando corresponde, con registros completos y verificación mediante entrevista y muestreo de registros. | U5: Implementation | V5: Registro | W5: Entrevista y muestreo de registros | X5: Grave | Y5: Soporte
B6: 5 | D6: Compromiso visible de la dirección y de los líderes | E6: S01.2 | F6: Ambos | G6: Exposición | H6: Fatiga y/o somnolencia en persona expuesta a tarea crítica | I6: Persona fatigada o somnolienta permanece en tarea crítica sin ser detectada ni intervenida | J6: Liderazgo visible en seguridad | K6: Que la dirección y los líderes demuestren con acciones, no solo con declaraciones, que los riesgos críticos son prioridad | L6: Acciones visibles de los líderes en terreno | M6: 5 | N6: ¿En qué medida supervisores y jefaturas realizan acciones concretas y visibles de seguridad durante el turno (conversaciones de riesgo, verificación de controles, detención de trabajos inseguros, atención a la fatiga del equipo), incluido el turno de noche? | O6: Ejemplos: observación de al menos 2 turnos (día y noche), registros de interacciones, relato de trabajadores | P6: El control asociado a «Acciones visibles de los líderes en terreno» no opera en la práctica o, cuando se requiere, no genera la acción esperada. | Q6: El control asociado a «Acciones visibles de los líderes en terreno» opera de forma esporádica y reactiva, depende de iniciativas individuales y carece de respuesta oportuna o registros consistentes. | R6: El control asociado a «Acciones visibles de los líderes en terreno» funciona parcialmente o de manera irregular; genera algunas acciones, pero presenta brechas relevantes de oportunidad, calidad, seguimiento o trazabilidad. | S6: El control asociado a «Acciones visibles de los líderes en terreno» funciona regularmente y genera la respuesta esperada en la mayoría de los casos; quedan desviaciones menores de oportunidad, cobertura o registro. | T6: El control asociado a «Acciones visibles de los líderes en terreno» funciona de manera confiable, oportuna y consistente en todos los casos aplicables, con acciones trazables, seguimiento y evidencia verificable mediante observación en terreno. | U6: Functioning | V6: Observación en terreno | W6: Observación en terreno | X6: Grave | Y6: Soporte
B7: 6 | D7: Compromiso visible de la dirección y de los líderes | E7: S01.2 | F7: Ambos | G7: Exposición | H7: Fatiga y/o somnolencia en persona expuesta a tarea crítica | I7: Persona fatigada o somnolienta permanece en tarea crítica sin ser detectada ni intervenida | J7: Liderazgo visible en seguridad | K7: Que la dirección y los líderes demuestren con acciones, no solo con declaraciones, que los riesgos críticos son prioridad | L7: Objetivos claros que incluyen la fatiga | M7: 6 | N7: ¿En qué medida la organización tiene objetivos claros y verificables para sus riesgos críticos, incluidas la fatiga y la somnolencia, y la línea de mando los conoce? | O7: Ejemplos: objetivos o metas escritos, planes de área, conocimiento de los objetivos por parte de las jefaturas entrevistadas | P7: El criterio «Objetivos claros que incluyen la fatiga» no está definido ni documentado; no existen criterios operativos, responsables ni evidencia aplicable. | Q7: El criterio «Objetivos claros que incluyen la fatiga» se aborda de manera informal o mediante documentos aislados, incompletos o desactualizados, sin alcance ni responsables claros. | R7: El criterio «Objetivos claros que incluyen la fatiga» está formalmente definido, pero cubre solo parte del alcance o presenta brechas relevantes de actualización, criterios, responsables o aprobación. | S7: El criterio «Objetivos claros que incluyen la fatiga» está definido, documentado, aprobado y vigente para la mayor parte del alcance; solo quedan brechas menores de cobertura o integración. | T7: El criterio «Objetivos claros que incluyen la fatiga» está completamente formalizado, aprobado, vigente e integrado a la gestión, con alcance, parámetros, responsables y revisión periódica verificables mediante revisión documental y entrevista. | U7: Design | V7: Documental | W7: Revisión documental y entrevista | X7: Grave | Y7: Administrativo
B8: 7 | D8: Decisiones y planificación que consideran los riesgos críticos | E8: S01.3 | F8: Ambos | G8: Exposición | H8: Fatiga y/o somnolencia en persona expuesta a tarea crítica | I8: Pérdida de control de equipo móvil o vehículo (colisión, volcamiento, salida de vía) | J8: Riesgo crítico integrado en decisiones y planificación | K8: Que la fatiga y los demás riesgos críticos se consideren antes de decidir y planificar la operación | L8: Mecanismos para decidir considerando los riesgos críticos | M8: 7 | N8: ¿En qué medida existen instancias o criterios para tomar decisiones operacionales (cambios de turno, extensiones de jornada, programación de tareas críticas, metas de producción) considerando explícitamente los riesgos críticos? | O8: Ejemplos: reuniones de planificación con revisión de riesgos, criterios de autorización, listas de verificación de decisiones | P8: El criterio «Mecanismos para decidir considerando los riesgos críticos» no está definido ni documentado; no existen criterios operativos, responsables ni evidencia aplicable. | Q8: El criterio «Mecanismos para decidir considerando los riesgos críticos» se aborda de manera informal o mediante documentos aislados, incompletos o desactualizados, sin alcance ni responsables claros. | R8: El criterio «Mecanismos para decidir considerando los riesgos críticos» está formalmente definido, pero cubre solo parte del alcance o presenta brechas relevantes de actualización, criterios, responsables o aprobación. | S8: El criterio «Mecanismos para decidir considerando los riesgos críticos» está definido, documentado, aprobado y vigente para la mayor parte del alcance; solo quedan brechas menores de cobertura o integración. | T8: El criterio «Mecanismos para decidir considerando los riesgos críticos» está completamente formalizado, aprobado, vigente e integrado a la gestión, con alcance, parámetros, responsables y revisión periódica verificables mediante revisión documental y entrevista. | U8: Design | V8: Documental | W8: Revisión documental y entrevista | X8: Grave | Y8: Administrativo
B9: 8 | D9: Decisiones y planificación que consideran los riesgos críticos | E9: S01.3 | F9: Ambos | G9: Exposición | H9: Fatiga y/o somnolencia en persona expuesta a tarea crítica | I9: Pérdida de control de equipo móvil o vehículo (colisión, volcamiento, salida de vía) | J9: Riesgo crítico integrado en decisiones y planificación | K9: Que la fatiga y los demás riesgos críticos se consideren antes de decidir y planificar la operación | L9: Seguridad integrada en la planificación real | M9: 8 | N9: ¿En qué medida la planificación diaria, semanal y de proyectos (por ejemplo, paradas de planta) incorpora en la práctica la dotación, los turnos y el control de la fatiga antes de comprometer metas o plazos? | O9: Ejemplos: muestra de planes y programas recientes comparados con la dotación y los turnos reales; entrevistas a planificadores y jefes de turno | P9: El control asociado a «Seguridad integrada en la planificación real» no opera en la práctica o, cuando se requiere, no genera la acción esperada. | Q9: El control asociado a «Seguridad integrada en la planificación real» opera de forma esporádica y reactiva, depende de iniciativas individuales y carece de respuesta oportuna o registros consistentes. | R9: El control asociado a «Seguridad integrada en la planificación real» funciona parcialmente o de manera irregular; genera algunas acciones, pero presenta brechas relevantes de oportunidad, calidad, seguimiento o trazabilidad. | S9: El control asociado a «Seguridad integrada en la planificación real» funciona regularmente y genera la respuesta esperada en la mayoría de los casos; quedan desviaciones menores de oportunidad, cobertura o registro. | T9: El control asociado a «Seguridad integrada en la planificación real» funciona de manera confiable, oportuna y consistente en todos los casos aplicables, con acciones trazables, seguimiento y evidencia verificable mediante reconstrucción de casos. | U9: Functioning | V9: Registro | W9: Reconstrucción de casos | X9: Fatal | Y9: Soporte
B10: 9 | D10: Decisiones y planificación que consideran los riesgos críticos | E10: S01.3 | F10: Ambos | G10: Exposición | H10: Fatiga y/o somnolencia en persona expuesta a tarea crítica | I10: Pérdida de control de equipo móvil o vehículo (colisión, volcamiento, salida de vía) | J10: Riesgo crítico integrado en decisiones y planificación | K10: Que la fatiga y los demás riesgos críticos se consideren antes de decidir y planificar la operación | L10: Revisión periódica de la dirección con datos | M10: 9 | N10: ¿En qué medida la dirección revisa periódicamente información sobre fatiga y riesgos críticos (exposición, alertas, eventos, desviaciones) y deja decisiones con responsable? | O10: Ejemplos: actas, presentaciones o correos de revisión con datos, decisiones y seguimiento | P10: No se verifica el criterio «Revisión periódica de la dirección con datos» y no existe evidencia de revisión del control o de sus resultados. | Q10: El criterio «Revisión periódica de la dirección con datos» se verifica solo de manera ocasional o informal, sin método, frecuencia, muestra ni seguimiento definidos. | R10: El criterio «Revisión periódica de la dirección con datos» cuenta con verificaciones periódicas pero parciales, con cobertura o profundidad insuficiente y seguimiento inconsistente de los hallazgos. | S10: El criterio «Revisión periódica de la dirección con datos» se verifica sistemáticamente en la mayor parte del alcance, con hallazgos registrados y acciones de seguimiento; quedan brechas menores. | T10: El criterio «Revisión periódica de la dirección con datos» se verifica de forma sistemática, independiente y basada en riesgo en todo el alcance, mediante revisión documental y muestreo, con cierre comprobado de hallazgos y retroalimentación al sistema. | U10: Verification | V10: Registro | W10: Revisión documental y muestreo | X10: Grave | Y10: Administrativo
B11: 10 | D11: Decisiones y planificación que consideran los riesgos críticos | E11: S01.3 | F11: Ambos | G11: Exposición | H11: Fatiga y/o somnolencia en persona expuesta a tarea crítica | I11: Pérdida de control de equipo móvil o vehículo (colisión, volcamiento, salida de vía) | J11: Riesgo crítico integrado en decisiones y planificación | K11: Que la fatiga y los demás riesgos críticos se consideren antes de decidir y planificar la operación | L11: Decisiones de la dirección con efecto medible | M11: 10 | N11: ¿En qué medida las decisiones tomadas sobre riesgos críticos se implementaron y muestran efecto en los resultados asociados (por ejemplo, menos turnos fuera de límite)? | O11: Ejemplos: comparación de datos antes y después de cada decisión, al menos 3 períodos | P11: El criterio «Decisiones de la dirección con efecto medible» no muestra resultados medibles o no se evalúa su efecto sobre el riesgo y el desempeño. | Q11: El criterio «Decisiones de la dirección con efecto medible» presenta resultados anecdóticos o aislados, sin línea base, indicadores comparables ni evidencia de mejora atribuible. | R11: El criterio «Decisiones de la dirección con efecto medible» dispone de algunos indicadores o comparaciones, pero los resultados son parciales, inestables o insuficientes para demostrar efectividad sostenida. | S11: El criterio «Decisiones de la dirección con efecto medible» muestra una mejora medible y mayormente sostenida en los resultados; persisten brechas menores o variaciones que requieren seguimiento. | T11: El criterio «Decisiones de la dirección con efecto medible» demuestra efectividad sostenida con datos comparables de al menos tres períodos, tendencia favorable y ausencia o reducción comprobada de recurrencias, verificada mediante análisis de datos. | U11: Effectiveness | V11: Análisis de tendencia | W11: Análisis de datos | X11: Grave | Y11: Administrativo
B12: 11 | D12: Decisiones y planificación que consideran los riesgos críticos | E12: S01.3 | F12: Ambos | G12: Exposición | H12: Fatiga y/o somnolencia en persona expuesta a tarea crítica | I12: Pérdida de control de equipo móvil o vehículo (colisión, volcamiento, salida de vía) | J12: Riesgo crítico integrado en decisiones y planificación | K12: Que la fatiga y los demás riesgos críticos se consideren antes de decidir y planificar la operación | L12: Recursos para los controles disponibles en cada turno | M12: 11 | N12: ¿En qué medida los recursos necesarios para controlar la fatiga (relevos, tecnología, apoyo de salud) están disponibles en todos los turnos y no solo en el turno de día? | O12: Ejemplos: dotación de relevos por turno comparada con la necesaria; disponibilidad real de equipos y apoyo | P12: El control asociado a «Recursos para los controles disponibles en cada turno» no opera en la práctica o, cuando se requiere, no genera la acción esperada. | Q12: El control asociado a «Recursos para los controles disponibles en cada turno» opera de forma esporádica y reactiva, depende de iniciativas individuales y carece de respuesta oportuna o registros consistentes. | R12: El control asociado a «Recursos para los controles disponibles en cada turno» funciona parcialmente o de manera irregular; genera algunas acciones, pero presenta brechas relevantes de oportunidad, calidad, seguimiento o trazabilidad. | S12: El control asociado a «Recursos para los controles disponibles en cada turno» funciona regularmente y genera la respuesta esperada en la mayoría de los casos; quedan desviaciones menores de oportunidad, cobertura o registro. | T12: El control asociado a «Recursos para los controles disponibles en cada turno» funciona de manera confiable, oportuna y consistente en todos los casos aplicables, con acciones trazables, seguimiento y evidencia verificable mediante análisis de datos. | U12: Functioning | V12: Registro | W12: Análisis de datos | X12: Grave | Y12: Administrativo
B13: 12 | D13: Comunicación entre niveles y participación de los trabajadores | E13: S01.4 | F13: Ambos | G13: Deterioro del desempeño humano | H13: Fatiga y/o somnolencia en persona expuesta a tarea crítica | I13: Persona fatigada o somnolienta permanece en tarea crítica sin ser detectada ni intervenida | J13: Canales de comunicación y participación | K13: Que la información de riesgo fluya en ambos sentidos y los trabajadores puedan plantear preocupaciones | L13: Comunicación efectiva entre niveles | M13: 12 | N13: ¿En qué medida la información sobre riesgos fluye en ambos sentidos entre la dirección, la supervisión y los trabajadores, y las preocupaciones planteadas reciben respuesta? | O13: Ejemplos: casos de preocupaciones planteadas y su respuesta; reuniones de turno observadas; relato de trabajadores y supervisores | P13: El control asociado a «Comunicación efectiva entre niveles» no opera en la práctica o, cuando se requiere, no genera la acción esperada. | Q13: El control asociado a «Comunicación efectiva entre niveles» opera de forma esporádica y reactiva, depende de iniciativas individuales y carece de respuesta oportuna o registros consistentes. | R13: El control asociado a «Comunicación efectiva entre niveles» funciona parcialmente o de manera irregular; genera algunas acciones, pero presenta brechas relevantes de oportunidad, calidad, seguimiento o trazabilidad. | S13: El control asociado a «Comunicación efectiva entre niveles» funciona regularmente y genera la respuesta esperada en la mayoría de los casos; quedan desviaciones menores de oportunidad, cobertura o registro. | T13: El control asociado a «Comunicación efectiva entre niveles» funciona de manera confiable, oportuna y consistente en todos los casos aplicables, con acciones trazables, seguimiento y evidencia verificable mediante entrevista y reconstrucción de casos. | U13: Functioning | V13: Entrevista | W13: Entrevista y reconstrucción de casos | X13: Grave | Y13: Soporte
B14: 13 | D14: Comunicación entre niveles y participación de los trabajadores | E14: S01.4 | F14: Ambos | G14: Deterioro del desempeño humano | H14: Fatiga y/o somnolencia en persona expuesta a tarea crítica | I14: Persona fatigada o somnolienta permanece en tarea crítica sin ser detectada ni intervenida | J14: Canales de comunicación y participación | K14: Que la información de riesgo fluya en ambos sentidos y los trabajadores puedan plantear preocupaciones | L14: Mecanismos de participación de los trabajadores | M14: 13 | N14: ¿En qué medida los trabajadores tienen y usan formas reales de participar y plantear preocupaciones sobre los riesgos (comités, reuniones, canales directos, participación en el diseño de turnos o tareas)? | O14: Ejemplos: actas o registros de participación; ejemplos concretos de cambios propuestos por trabajadores | P14: El criterio «Mecanismos de participación de los trabajadores» no se aplica en la práctica y no existe evidencia de implementación. | Q14: El criterio «Mecanismos de participación de los trabajadores» se aplica solo en casos aislados o de manera informal, sin cobertura planificada ni consistencia entre áreas, turnos o personas expuestas. | R14: El criterio «Mecanismos de participación de los trabajadores» está implementado parcialmente; alcanza parte de la población o del proceso, con brechas relevantes de cobertura, frecuencia o registro. | S14: El criterio «Mecanismos de participación de los trabajadores» está implementado de forma regular en la mayor parte del alcance y con evidencia suficiente; persisten brechas menores de cobertura o consistencia. | T14: El criterio «Mecanismos de participación de los trabajadores» está implementado sistemáticamente en todo el alcance aplicable, incluidos turnos y contratistas cuando corresponde, con registros completos y verificación mediante entrevista y muestreo de registros. | U14: Implementation | V14: Registro | W14: Entrevista y muestreo de registros | X14: Grave | Y14: Soporte
... B18: 17 | D18: Gestión de la fatiga en empresas contratistas | E18: S01.6 | F18: Ambos | G18: Exposición | H18: Fatiga y/o somnolencia en persona expuesta a tarea crítica | I18: Pérdida de control de equipo móvil o vehículo (colisión, volcamiento, salida de vía) | J18: Requisitos de fatiga para contratistas | K18: Extender los controles a toda persona expuesta, independiente del empleador | L18: Jornadas de contratistas verificadas con datos | M18: 17 | N18: ¿En qué medida se verifica con datos (control de acceso, registros de turnos) que los contratistas cumplen los límites de jornada y descanso? | O18: Ejemplos: cruce de control de acceso con los límites, por empresa, últimos 3 meses | P18: No se verifica el criterio «Jornadas de contratistas verificadas con datos» y no existe evidencia de revisión del control o de sus resultados. | Q18: El criterio «Jornadas de contratistas verificadas con datos» se verifica solo de manera ocasional o informal, sin método, frecuencia, muestra ni seguimiento definidos. | R18: El criterio «Jornadas de contratistas verificadas con datos» cuenta con verificaciones periódicas pero parciales, con cobertura o profundidad insuficiente y seguimiento inconsistente de los hallazgos. | S18: El criterio «Jornadas de contratistas verificadas con datos» se verifica sistemáticamente en la mayor parte del alcance, con hallazgos registrados y acciones de seguimiento; quedan brechas menores. | T18: El criterio «Jornadas de contratistas verificadas con datos» se verifica de forma sistemática, independiente y basada en riesgo en todo el alcance, mediante análisis de datos, con cierre comprobado de hallazgos y retroalimentación al sistema. | U18: Verification | V18: Datos de sistema | W18: Análisis de datos | X18: Fatal | Y18: Soporte
B19: 18 | C19: D.2 Gestión del riesgo de fatiga | D19: Tareas críticas y población expuesta | E19: S02.1 | F19: Ambos | G19: Exposición | H19: Fatiga y/o somnolencia en persona expuesta a tarea crítica | I19: Pérdida de control de equipo móvil o vehículo (colisión, volcamiento, salida de vía) | J19: Inventario de tareas críticas sensibles a fatiga | K19: Saber quién está expuesto, dónde y cuándo | L19: Tareas críticas y población expuesta identificadas | M19: 1 | N19: ¿En qué medida la organización sabe qué tareas y cargos son sensibles a la fatiga o la somnolencia (equipos móviles, aislamiento, izaje, conducción, operación de planta) y cuántas personas están expuestas en cada turno? | O19: Ejemplos: listado de tareas o cargos críticos con dotación por turno; si no existe, lo que pueden indicar las jefaturas | P19: El criterio «Tareas críticas y población expuesta identificadas» no está definido ni documentado; no existen criterios operativos, responsables ni evidencia aplicable. | Q19: El criterio «Tareas críticas y población expuesta identificadas» se aborda de manera informal o mediante documentos aislados, incompletos o desactualizados, sin alcance ni responsables claros. | R19: El criterio «Tareas críticas y población expuesta identificadas» está formalmente definido, pero cubre solo parte del alcance o presenta brechas relevantes de actualización, criterios, responsables o aprobación. | S19: El criterio «Tareas críticas y población expuesta identificadas» está definido, documentado, aprobado y vigente para la mayor parte del alcance; solo quedan brechas menores de cobertura o integración. | T19: El criterio «Tareas críticas y población expuesta identificadas» está completamente formalizado, aprobado, vigente e integrado a la gestión, con alcance, parámetros, responsables y revisión periódica verificables mediante revisión documental y entrevista. | U19: Design | V19: Documental | W19: Revisión documental y entrevista | X19: Fatal | Y19: Soporte
